<?xml version="1.0" ?>
<!-- Generated using onshape-to-robot -->
<!-- Onshape https://cad.onshape.com/documents/95619c5a3c37ea0971576814/w/26610785af7f329813cd57b4/e/6cae43dcd495e7a1a823b044 -->
<robot name="hopejr">
  <!-- Link thorax_02d -->
  <link name="thorax_02d">
    <inertial>
      <origin xyz="0.00407148 -6.96142e-06 0.0378596" rpy="0 0 0"/>
      <mass value="2.96528"/>
      <inertia ixx="0.0726612" ixy="0.000120496" ixz="-0.00295857" iyy="0.0560882" iyz="-1.92068e-05" izz="0.031721"/>
    </inertial>
    <!-- Part mirrorchest_03 -->
    <visual>
      <origin xyz="0.00225538 0.126191 -0.0258308" rpy="-7.26627e-24 6.95699e-23 -1.66798"/>
      <geometry>
        <mesh filename="package://assets/mirrorchest_03.stl"/>
      </geometry>
      <material name="mirrorchest_03_material">
        <color rgba="0.647059 0.647059 0.647059 1.0"/>
      </material>
    </visual>
    <collision>
      <origin xyz="0.00225538 0.126191 -0.0258308" rpy="-7.26627e-24 6.95699e-23 -1.66798"/>
      <geometry>
        <mesh filename="package://assets/mirrorchest_03.stl"/>
      </geometry>
    </collision>
    <!-- Part head_mock_up_01g -->
    <visual>
      <origin xyz="0.0278313 0.000209681 0.223922" rpy="1.5708 1.72023e-18 0.00753384"/>
      <geometry>
        <mesh filename="package://assets/head_mock_up_01g.stl"/>
      </geometry>
      <material name="head_mock_up_01g_material">
        <color rgba="0.615686 0.811765 0.929412 1.0"/>
      </material>
    </visual>
    <collision>
      <origin xyz="0.0278313 0.000209681 0.223922" rpy="1.5708 1.72023e-18 0.00753384"/>
      <geometry>
        <mesh filename="package://assets/head_mock_up_01g.stl"/>
      </geometry>
    </collision>
    <!-- Part thorax_02d -->
    <visual>
      <origin xyz="9.37011e-19 -4.16241e-17 -0.07" rpy="-4.557e-26 -2.20235e-23 1.57833"/>
      <geometry>
        <mesh filename="package://assets/thorax_02d.stl"/>
      </geometry>
      <material name="thorax_02d_material">
        <color rgba="0.768627 0.886275 0.952941 1.0"/>
      </material>
    </visual>
    <collision>
      <origin xyz="9.37011e-19 -4.16241e-17 -0.07" rpy="-4.557e-26 -2.20235e-23 1.57833"/>
      <geometry>
        <mesh filename="package://assets/thorax_02d.stl"/>
      </geometry>
    </collision>
    <!-- Part chest_03 -->
    <visual>
      <origin xyz="0.00415646 -0.126143 -0.0258308" rpy="3.14159 -6.95603e-23 1.68305"/>
      <geometry>
        <mesh filename="package://assets/chest_03.stl"/>
      </geometry>
      <material name="chest_03_material">
        <color rgba="0.231373 0.380392 0.705882 1.0"/>
      </material>
    </visual>
    <collision>
      <origin xyz="0.00415646 -0.126143 -0.0258308" rpy="3.14159 -6.95603e-23 1.68305"/>
      <geometry>
        <mesh filename="package://assets/chest_03.stl"/>
      </geometry>
    </collision>
    <!-- Part mirrormantle_01f -->
    <visual>
      <origin xyz="0.00225538 0.126191 -0.0258308" rpy="3.14159 3.7795e-23 -1.66798"/>
      <geometry>
        <mesh filename="package://assets/mirrormantle_01f.stl"/>
      </geometry>
      <material name="mirrormantle_01f_material">
        <color rgba="0.980392 0.713725 0.00392157 1.0"/>
      </material>
    </visual>
    <collision>
      <origin xyz="0.00225538 0.126191 -0.0258308" rpy="3.14159 3.7795e-23 -1.66798"/>
      <geometry>
        <mesh filename="package://assets/mirrormantle_01f.stl"/>
      </geometry>
    </collision>
    <!-- Part mantle_01f -->
    <visual>
      <origin xyz="0.00415646 -0.126143 -0.0258308" rpy="1.44344e-15 -3.77855e-23 1.68305"/>
      <geometry>
        <mesh filename="package://assets/mantle_01f.stl"/>
      </geometry>
      <material name="mantle_01f_material">
        <color rgba="0.647059 0.647059 0.647059 1.0"/>
      </material>
    </visual>
    <collision>
      <origin xyz="0.00415646 -0.126143 -0.0258308" rpy="1.44344e-15 -3.77855e-23 1.68305"/>
      <geometry>
        <mesh filename="package://assets/mantle_01f.stl"/>
      </geometry>
    </collision>
  </link>
  <!-- Frame imu (dummy link + fixed joint) -->
  <link name="imu">
    <origin xyz="0 0 0" rpy="0 -0 0"/>
    <inertial>
      <origin xyz="0 0 0" rpy="0 0 0"/>
      <mass value="1e-9"/>
      <inertia ixx="0" ixy="0" ixz="0" iyy="0" iyz="0" izz="0"/>
    </inertial>
  </link>
  <joint name="imu_frame" type="fixed">
    <origin xyz="-0.0674981 -0.00050853 0.0961692" rpy="2.20235e-23 -4.557e-26 0.00753384"/>
    <parent link="thorax_02d"/>
    <child link="imu"/>
    <axis xyz="0 0 0"/>
  </joint>
  <!-- Link waist_04d -->
  <link name="waist_04d">
    <inertial>
      <origin xyz="-2.06113e-05 -0.0190493 0.128965" rpy="0 0 0"/>
      <mass value="1.05048"/>
      <inertia ixx="0.0126444" ixy="1.94178e-05" ixz="-7.73776e-06" iyy="0.0105285" iyz="0.000992709" izz="0.00422168"/>
    </inertial>
    <!-- Part waist_04d -->
    <visual>
      <origin xyz="9.71918e-17 -7.14389e-18 0.296" rpy="-1.5708 1.20351e-25 1.57833"/>
      <geometry>
        <mesh filename="package://assets/waist_04d.stl"/>
      </geometry>
      <material name="waist_04d_material">
        <color rgba="0.615686 0.811765 0.929412 1.0"/>
      </material>
    </visual>
    <collision>
      <origin xyz="9.71918e-17 -7.14389e-18 0.296" rpy="-1.5708 1.20351e-25 1.57833"/>
      <geometry>
        <mesh filename="package://assets/waist_04d.stl"/>
      </geometry>
    </collision>
  </link>
  <!-- Link torso_pitch_yaw_03 -->
  <link name="torso_pitch_yaw_03">
    <inertial>
      <origin xyz="0.0530911 -0.0187022 -0.0786225" rpy="0 0 0"/>
      <mass value="0.439769"/>
      <inertia ixx="0.0010388" ixy="0.000155504" ixz="-0.000249465" iyy="0.00167533" iyz="7.29288e-05" izz="0.00124827"/>
    </inertial>
    <!-- Part torso_pitch_yaw_03 -->
    <visual>
      <origin xyz="5.55112e-16 -1.22189e-17 -0.068" rpy="-3.18511e-32 -3.74795e-16 -1.5708"/>
      <geometry>
        <mesh filename="package://assets/torso_pitch_yaw_03.stl"/>
      </geometry>
      <material name="torso_pitch_yaw_03_material">
        <color rgba="0.917647 0.917647 0.917647 1.0"/>
      </material>
    </visual>
    <collision>
      <origin xyz="5.55112e-16 -1.22189e-17 -0.068" rpy="-3.18511e-32 -3.74795e-16 -1.5708"/>
      <geometry>
        <mesh filename="package://assets/torso_pitch_yaw_03.stl"/>
      </geometry>
    </collision>
  </link>
  <!-- Link pelvis_08 -->
  <link name="pelvis_08">
    <inertial>
      <origin xyz="-0.0734106 3.81385e-06 0" rpy="0 0 0"/>
      <mass value="0.749221"/>
      <inertia ixx="0.00112457" ixy="-1.56701e-20" ixz="1.5992e-18" iyy="0.00298368" iyz="-1.77544e-07" izz="0.00262983"/>
    </inertial>
    <!-- Part pelvis_08 -->
    <visual>
      <origin xyz="0 0 6.16298e-33" rpy="-1.5708 -1.5708 0"/>
      <geometry>
        <mesh filename="package://assets/pelvis_08.stl"/>
      </geometry>
      <material name="pelvis_08_material">
        <color rgba="0.498039 0.498039 0.498039 1.0"/>
      </material>
    </visual>
    <collision>
      <origin xyz="0 0 6.16298e-33" rpy="-1.5708 -1.5708 0"/>
      <geometry>
        <mesh filename="package://assets/pelvis_08.stl"/>
      </geometry>
    </collision>
    <!-- Part pelvis_08_2 -->
    <visual>
      <origin xyz="0 7.62771e-06 -8.46846e-22" rpy="1.5708 1.5708 0"/>
      <geometry>
        <mesh filename="package://assets/pelvis_08.stl"/>
      </geometry>
      <material name="pelvis_08_2_material">
        <color rgba="0.498039 0.498039 0.498039 1.0"/>
      </material>
    </visual>
    <collision>
      <origin xyz="0 7.62771e-06 -8.46846e-22" rpy="1.5708 1.5708 0"/>
      <geometry>
        <mesh filename="package://assets/pelvis_08.stl"/>
      </geometry>
    </collision>
  </link>
  <!-- Frame trunk (dummy link + fixed joint) -->
  <link name="trunk">
    <origin xyz="0 0 0" rpy="0 -0 0"/>
    <inertial>
      <origin xyz="0 0 0" rpy="0 0 0"/>
      <mass value="1e-9"/>
      <inertia ixx="0" ixy="0" ixz="0" iyy="0" iyz="0" izz="0"/>
    </inertial>
  </link>
  <joint name="trunk_frame" type="fixed">
    <origin xyz="-0.121965 0.0002 -0.0002" rpy="-1.5708 1.44553e-31 -1.5708"/>
    <parent link="pelvis_08"/>
    <child link="trunk"/>
    <axis xyz="0 0 0"/>
  </joint>
  <!-- Link m5_80_pulley_03h_52 -->
  <link name="m5_80_pulley_03h_52">
    <inertial>
      <origin xyz="0.0365809 -0.0178295 -0.0552817" rpy="0 0 0"/>
      <mass value="0.278929"/>
      <inertia ixx="0.00073759" ixy="-8.41197e-05" ixz="6.9547e-06" iyy="0.000438867" iyz="-5.50361e-05" izz="0.000456455"/>
    </inertial>
    <!-- Part m5_80_pulley_03h_52 -->
    <visual>
      <origin xyz="0 -5.55112e-17 -0.00442511" rpy="3.14159 -3.37623e-32 6.46702e-31"/>
      <geometry>
        <mesh filename="package://assets/m5_80_pulley_03h_52.stl"/>
      </geometry>
      <material name="m5_80_pulley_03h_52_material">
        <color rgba="0.498039 0.498039 0.498039 1.0"/>
      </material>
    </visual>
    <collision>
      <origin xyz="0 -5.55112e-17 -0.00442511" rpy="3.14159 -3.37623e-32 6.46702e-31"/>
      <geometry>
        <mesh filename="package://assets/m5_80_pulley_03h_52.stl"/>
      </geometry>
    </collision>
  </link>
  <!-- Link cybergear_02b -->
  <link name="cybergear_02b">
    <inertial>
      <origin xyz="-0.067085 0.00607879 0.0591296" rpy="0 0 0"/>
      <mass value="0.615535"/>
      <inertia ixx="0.000490498" ixy="9.42627e-06" ixz="4.965e-05" iyy="0.000570176" iyz="-4.55443e-06" izz="0.000521906"/>
    </inertial>
    <!-- Part sea_spring_mount_05i_hip_yaw -->
    <visual>
      <origin xyz="3.88578e-16 4.53804e-15 0.0608" rpy="-1.65806 -1.5708 0"/>
      <geometry>
        <mesh filename="package://assets/sea_spring_mount_05i_hip_yaw.stl"/>
      </geometry>
      <material name="sea_spring_mount_05i_hip_yaw_material">
        <color rgba="0.647059 0.647059 0.647059 1.0"/>
      </material>
    </visual>
    <collision>
      <origin xyz="3.88578e-16 4.53804e-15 0.0608" rpy="-1.65806 -1.5708 0"/>
      <geometry>
        <mesh filename="package://assets/sea_spring_mount_05i_hip_yaw.stl"/>
      </geometry>
    </collision>
    <!-- Part cybergear_02b -->
    <visual>
      <origin xyz="-0.0627528 0.00557574 0.0606759" rpy="-1.48353 1.5708 0"/>
      <geometry>
        <mesh filename="package://assets/cybergear_02b.stl"/>
      </geometry>
      <material name="cybergear_02b_material">
        <color rgba="0.972549 0.529412 0.00392157 1.0"/>
      </material>
    </visual>
    <collision>
      <origin xyz="-0.0627528 0.00557574 0.0606759" rpy="-1.48353 1.5708 0"/>
      <geometry>
        <mesh filename="package://assets/cybergear_02b.stl"/>
      </geometry>
    </collision>
    <!-- Part sea_spring_mount_05i_hip_yaw_2 -->
    <visual>
      <origin xyz="0 1.38778e-17 0.0608" rpy="-1.65806 -1.5708 0"/>
      <geometry>
        <mesh filename="package://assets/sea_spring_mount_05i_hip_yaw__2.stl"/>
      </geometry>
      <material name="sea_spring_mount_05i_hip_yaw_2_material">
        <color rgba="0.917647 0.917647 0.917647 1.0"/>
      </material>
    </visual>
    <collision>
      <origin xyz="0 1.38778e-17 0.0608" rpy="-1.65806 -1.5708 0"/>
      <geometry>
        <mesh filename="package://assets/sea_spring_mount_05i_hip_yaw__2.stl"/>
      </geometry>
    </collision>
  </link>
  <!-- Link sea_humeral_01ka_femoral -->
  <link name="sea_humeral_01ka_femoral">
    <inertial>
      <origin xyz="0.0051361 0.0239822 -0.135017" rpy="0 0 0"/>
      <mass value="0.603133"/>
      <inertia ixx="0.00238729" ixy="0.000100328" ixz="0.000213836" iyy="0.0025162" iyz="-6.29989e-05" izz="0.000658941"/>
    </inertial>
    <!-- Part sea_humeral_01ka_femoral -->
    <visual>
      <origin xyz="-0.01 0.0019 -0.2169" rpy="1.5708 8.11271e-16 1.5708"/>
      <geometry>
        <mesh filename="package://assets/sea_humeral_01ka_femoral.stl"/>
      </geometry>
      <material name="sea_humeral_01ka_femoral_material">
        <color rgba="0.917647 0.917647 0.917647 1.0"/>
      </material>
    </visual>
    <collision>
      <origin xyz="-0.01 0.0019 -0.2169" rpy="1.5708 8.11271e-16 1.5708"/>
      <geometry>
        <mesh filename="package://assets/sea_humeral_01ka_femoral.stl"/>
      </geometry>
    </collision>
    <!-- Part sea_spring_mount_05i_arm_rotation -->
    <visual>
      <origin xyz="0 -2.77556e-17 -0.0393" rpy="3.14159 -1.5708 0"/>
      <geometry>
        <mesh filename="package://assets/sea_spring_mount_05i_arm_rotation.stl"/>
      </geometry>
      <material name="sea_spring_mount_05i_arm_rotation_material">
        <color rgba="0.647059 0.647059 0.647059 1.0"/>
      </material>
    </visual>
    <collision>
      <origin xyz="0 -2.77556e-17 -0.0393" rpy="3.14159 -1.5708 0"/>
      <geometry>
        <mesh filename="package://assets/sea_spring_mount_05i_arm_rotation.stl"/>
      </geometry>
    </collision>
  </link>
  <!-- Link sea_ankle_02e -->
  <link name="sea_ankle_02e">
    <inertial>
      <origin xyz="-0.152143 0.00248448 0.0356482" rpy="0 0 0"/>
      <mass value="0.698353"/>
      <inertia ixx="0.000700514" ixy="0.000140851" ixz="-0.000302545" iyy="0.00482338" iyz="-4.50357e-05" izz="0.00474653"/>
    </inertial>
    <!-- Part sea_ankle_02e -->
    <visual>
      <origin xyz="-0.266 1.05e-08 0.0516" rpy="1.5708 1.5708 0"/>
      <geometry>
        <mesh filename="package://assets/sea_ankle_02e.stl"/>
      </geometry>
      <material name="sea_ankle_02e_material">
        <color rgba="0.231373 0.380392 0.705882 1.0"/>
      </material>
    </visual>
    <collision>
      <origin xyz="-0.266 1.05e-08 0.0516" rpy="1.5708 1.5708 0"/>
      <geometry>
        <mesh filename="package://assets/sea_ankle_02e.stl"/>
      </geometry>
    </collision>
    <!-- Part sea_spring_mount_05i_small_knee -->
    <visual>
      <origin xyz="-1.11022e-16 1.73472e-18 0.055" rpy="-1.5708 -1.5708 0"/>
      <geometry>
        <mesh filename="package://assets/sea_spring_mount_05i_small_knee.stl"/>
      </geometry>
      <material name="sea_spring_mount_05i_small_knee_material">
        <color rgba="0.972549 0.529412 0.00392157 1.0"/>
      </material>
    </visual>
    <collision>
      <origin xyz="-1.11022e-16 1.73472e-18 0.055" rpy="-1.5708 -1.5708 0"/>
      <geometry>
        <mesh filename="package://assets/sea_spring_mount_05i_small_knee.stl"/>
      </geometry>
    </collision>
  </link>
  <!-- Link sea_spring_mount_05i_ankle -->
  <link name="sea_spring_mount_05i_ankle">
    <inertial>
      <origin xyz="-0.0407821 -0.0158188 0.0504789" rpy="0 0 0"/>
      <mass value="0.239095"/>
      <inertia ixx="0.000211094" ixy="3.3963e-05" ixz="2.54306e-05" iyy="0.000223022" iyz="6.719e-06" izz="0.000193976"/>
    </inertial>
    <!-- Part sea_spring_mount_05i_ankle -->
    <visual>
      <origin xyz="9.55615e-05 3.44826e-05 0.0548" rpy="-1.0472 -1.5708 0"/>
      <geometry>
        <mesh filename="package://assets/sea_spring_mount_05i_ankle.stl"/>
      </geometry>
      <material name="sea_spring_mount_05i_ankle_material">
        <color rgba="0.768627 0.886275 0.952941 1.0"/>
      </material>
    </visual>
    <collision>
      <origin xyz="9.55615e-05 3.44826e-05 0.0548" rpy="-1.0472 -1.5708 0"/>
      <geometry>
        <mesh filename="package://assets/sea_spring_mount_05i_ankle.stl"/>
      </geometry>
    </collision>
    <!-- Part sea_spring_mount_05i_ankle_2 -->
    <visual>
      <origin xyz="-4.44089e-16 -2.60209e-18 0.0548" rpy="-1.0472 -1.5708 0"/>
      <geometry>
        <mesh filename="package://assets/sea_spring_mount_05i_ankle__2.stl"/>
      </geometry>
      <material name="sea_spring_mount_05i_ankle_2_material">
        <color rgba="0.498039 0.498039 0.498039 1.0"/>
      </material>
    </visual>
    <collision>
      <origin xyz="-4.44089e-16 -2.60209e-18 0.0548" rpy="-1.0472 -1.5708 0"/>
      <geometry>
        <mesh filename="package://assets/sea_spring_mount_05i_ankle__2.stl"/>
      </geometry>
    </collision>
  </link>
  <!-- Link heel_04b -->
  <link name="heel_04b">
    <inertial>
      <origin xyz="-0.0012217 0.00542904 0.0247931" rpy="0 0 0"/>
      <mass value="0.381627"/>
      <inertia ixx="0.00132369" ixy="-1.79076e-05" ixz="-2.38176e-05" iyy="0.00128054" iyz="-0.000346293" izz="0.000546581"/>
    </inertial>
    <!-- Part heel_04b -->
    <visual>
      <origin xyz="4.85584e-14 0.0351 0.0432218" rpy="2.0944 7.73705e-16 3.14159"/>
      <geometry>
        <mesh filename="package://assets/heel_04b.stl"/>
      </geometry>
      <material name="heel_04b_material">
        <color rgba="0.647059 0.647059 0.647059 1.0"/>
      </material>
    </visual>
    <collision>
      <origin xyz="4.85584e-14 0.0351 0.0432218" rpy="2.0944 7.73705e-16 3.14159"/>
      <geometry>
        <mesh filename="package://assets/heel_04b.stl"/>
      </geometry>
    </collision>
    <!-- Part heel_04b_2 -->
    <visual>
      <origin xyz="4.85723e-14 0.0351 0.0432218" rpy="2.0944 8.45816e-16 3.14159"/>
      <geometry>
        <mesh filename="package://assets/heel_04b__2.stl"/>
      </geometry>
      <material name="heel_04b_2_material">
        <color rgba="0.231373 0.380392 0.705882 1.0"/>
      </material>
    </visual>
    <collision>
      <origin xyz="4.85723e-14 0.0351 0.0432218" rpy="2.0944 8.45816e-16 3.14159"/>
      <geometry>
        <mesh filename="package://assets/heel_04b__2.stl"/>
      </geometry>
    </collision>
    <!-- Part right_foot_heel_collision -->
    <visual>
      <origin xyz="-0.00669903 0.0260668 0.00374903" rpy="-1.69907e-15 -1.0472 1.5708"/>
      <geometry>
        <mesh filename="package://assets/right_foot_heel_collision.stl"/>
      </geometry>
      <material name="right_foot_heel_collision_material">
        <color rgba="0.615686 0.811765 0.929412 1.0"/>
      </material>
    </visual>
    <collision>
      <origin xyz="-0.00669903 0.0260668 0.00374903" rpy="-1.69907e-15 -1.0472 1.5708"/>
      <geometry>
        <mesh filename="package://assets/right_foot_heel_collision.stl"/>
      </geometry>
    </collision>
    <!-- Part heel_04b_3 -->
    <visual>
      <origin xyz="4.84196e-14 0.035 0.0432218" rpy="2.0944 8.49534e-16 3.14159"/>
      <geometry>
        <mesh filename="package://assets/heel_04b__3.stl"/>
      </geometry>
      <material name="heel_04b_3_material">
        <color rgba="0.615686 0.811765 0.929412 1.0"/>
      </material>
    </visual>
    <collision>
      <origin xyz="4.84196e-14 0.035 0.0432218" rpy="2.0944 8.49534e-16 3.14159"/>
      <geometry>
        <mesh filename="package://assets/heel_04b__3.stl"/>
      </geometry>
    </collision>
  </link>
  <!-- Frame right_foot (dummy link + fixed joint) -->
  <link name="right_foot">
    <origin xyz="0 0 0" rpy="0 -0 0"/>
    <inertial>
      <origin xyz="0 0 0" rpy="0 0 0"/>
      <mass value="1e-9"/>
      <inertia ixx="0" ixy="0" ixz="0" iyy="0" iyz="0" izz="0"/>
    </inertial>
  </link>
  <joint name="right_foot_frame" type="fixed">
    <origin xyz="4.57689e-14 0.0330533 0.02085" rpy="-1.69907e-15 -1.0472 1.5708"/>
    <parent link="heel_04b"/>
    <child link="right_foot"/>
    <axis xyz="0 0 0"/>
  </joint>
  <!-- Link toes_04b -->
  <link name="toes_04b">
    <inertial>
      <origin xyz="0.0273128 0.00913029 -0.0303434" rpy="0 0 0"/>
      <mass value="0.0758636"/>
      <inertia ixx="4.76773e-05" ixy="-8.9882e-06" ixz="-4.76658e-06" iyy="7.74599e-05" iyz="-1.14422e-06" izz="4.42092e-05"/>
    </inertial>
    <!-- Part right_foot_toe_collision -->
    <visual>
      <origin xyz="-0.086327 0.021 -0.0270872" rpy="1.5708 4.08189e-16 3.39024e-17"/>
      <geometry>
        <mesh filename="package://assets/right_foot_toe_collision.stl"/>
      </geometry>
      <material name="right_foot_toe_collision_material">
        <color rgba="0.647059 0.647059 0.647059 1.0"/>
      </material>
    </visual>
    <collision>
      <origin xyz="-0.086327 0.021 -0.0270872" rpy="1.5708 4.08189e-16 3.39024e-17"/>
      <geometry>
        <mesh filename="package://assets/right_foot_toe_collision.stl"/>
      </geometry>
    </collision>
    <!-- Part toes_04b -->
    <visual>
      <origin xyz="-0.048 0.009 -0.0345" rpy="-1.5708 -1.5708 0"/>
      <geometry>
        <mesh filename="package://assets/toes_04b.stl"/>
      </geometry>
      <material name="toes_04b_material">
        <color rgba="0.972549 0.529412 0.00392157 1.0"/>
      </material>
    </visual>
    <collision>
      <origin xyz="-0.048 0.009 -0.0345" rpy="-1.5708 -1.5708 0"/>
      <geometry>
        <mesh filename="package://assets/toes_04b.stl"/>
      </geometry>
    </collision>
    <!-- Part toes_04b_2 -->
    <visual>
      <origin xyz="-0.048 0.009 -0.0344" rpy="-1.5708 -1.5708 0"/>
      <geometry>
        <mesh filename="package://assets/toes_04b__2.stl"/>
      </geometry>
      <material name="toes_04b_2_material">
        <color rgba="0.498039 0.498039 0.498039 1.0"/>
      </material>
    </visual>
    <collision>
      <origin xyz="-0.048 0.009 -0.0344" rpy="-1.5708 -1.5708 0"/>
      <geometry>
        <mesh filename="package://assets/toes_04b__2.stl"/>
      </geometry>
    </collision>
    <!-- Part toes_04b_3 -->
    <visual>
      <origin xyz="-0.048 0.009 -0.0343" rpy="-1.5708 -1.5708 0"/>
      <geometry>
        <mesh filename="package://assets/toes_04b__3.stl"/>
      </geometry>
      <material name="toes_04b_3_material">
        <color rgba="0.980392 0.713725 0.00392157 1.0"/>
      </material>
    </visual>
    <collision>
      <origin xyz="-0.048 0.009 -0.0343" rpy="-1.5708 -1.5708 0"/>
      <geometry>
        <mesh filename="package://assets/toes_04b__3.stl"/>
      </geometry>
    </collision>
  </link>
  <!-- Joint from heel_04b to toes_04b -->
  <joint name="right_toe" type="revolute">
    <origin xyz="-0.0345 0.0512058 0.089291" rpy="-1.5708 -1.0472 1.5708"/>
    <parent link="heel_04b"/>
    <child link="toes_04b"/>
    <axis xyz="0 0 1"/>
    <limit effort="10" velocity="10" lower="-3.141592653589793" upper="3.141592653589793"/>
  </joint>
  <!-- Joint from sea_spring_mount_05i_ankle to heel_04b -->
  <joint name="right_ankle_roll" type="revolute">
    <origin xyz="-0.078798 0.0126822 0.0548" rpy="2.0944 -1.5708 0"/>
    <parent link="sea_spring_mount_05i_ankle"/>
    <child link="heel_04b"/>
    <axis xyz="0 0 1"/>
    <limit effort="10" velocity="10" lower="-3.141592653589793" upper="3.141592653589793"/>
  </joint>
  <!-- Joint from sea_ankle_02e to sea_spring_mount_05i_ankle -->
  <joint name="right_ankle_pitch" type="revolute">
    <origin xyz="-0.266 1.05e-08 -0.0051" rpy="1.20965e-14 3.20041e-15 -3.94738e-08"/>
    <parent link="sea_ankle_02e"/>
    <child link="sea_spring_mount_05i_ankle"/>
    <axis xyz="0 0 1"/>
    <limit effort="10" velocity="10" lower="-3.141592653589793" upper="3.141592653589793"/>
  </joint>
  <!-- Joint from sea_humeral_01ka_femoral to sea_ankle_02e -->
  <joint name="right_knee" type="revolute">
    <origin xyz="-0.01 0.0586 -0.2169" rpy="1.5708 -1.5708 0"/>
    <parent link="sea_humeral_01ka_femoral"/>
    <child link="sea_ankle_02e"/>
    <axis xyz="0 0 1"/>
    <limit effort="10" velocity="10" lower="-3.141592653589793" upper="3.141592653589793"/>
  </joint>
  <!-- Joint from cybergear_02b to sea_humeral_01ka_femoral -->
  <joint name="right_hip_yaw" type="revolute">
    <origin xyz="-0.0958265 0.00846931 0.0606759" rpy="0.0872665 1.5708 0"/>
    <parent link="cybergear_02b"/>
    <child link="sea_humeral_01ka_femoral"/>
    <axis xyz="0 0 1"/>
    <limit effort="10" velocity="10" lower="-3.141592653589793" upper="3.141592653589793"/>
  </joint>
  <!-- Joint from m5_80_pulley_03h_52 to cybergear_02b -->
  <joint name="right_hip_roll" type="revolute">
    <origin xyz="0.061 0 -0.0794251" rpy="1.5708 -2.28973e-18 -1.5708"/>
    <parent link="m5_80_pulley_03h_52"/>
    <child link="cybergear_02b"/>
    <axis xyz="0 0 1"/>
    <limit effort="10" velocity="10" lower="-3.141592653589793" upper="3.141592653589793"/>
  </joint>
  <!-- Joint from pelvis_08 to m5_80_pulley_03h_52 -->
  <joint name="right_hip_pitch" type="revolute">
    <origin xyz="-0.126943 7.62771e-06 0.0499415" rpy="3.05433 2.31199e-15 -1.5708"/>
    <parent link="pelvis_08"/>
    <child link="m5_80_pulley_03h_52"/>
    <axis xyz="0 0 1"/>
    <limit effort="10" velocity="10" lower="-3.141592653589793" upper="3.141592653589793"/>
  </joint>
  <!-- Link mirrorm5_80_pulley_03h_52 -->
  <link name="mirrorm5_80_pulley_03h_52">
    <inertial>
      <origin xyz="0.0178295 -0.0365821 -0.0483598" rpy="0 0 0"/>
      <mass value="0.278927"/>
      <inertia ixx="0.00043888" ixy="-8.41168e-05" ixz="5.50391e-05" iyy="0.000737595" iyz="-6.9516e-06" izz="0.000456439"/>
    </inertial>
    <!-- Part mirrorm5_80_pulley_03h_52 -->
    <visual>
      <origin xyz="-5.55112e-17 8.67362e-19 0.00249989" rpy="-1.52297e-16 7.23982e-17 -1.5708"/>
      <geometry>
        <mesh filename="package://assets/mirrorm5_80_pulley_03h_52.stl"/>
      </geometry>
      <material name="mirrorm5_80_pulley_03h_52_material">
        <color rgba="0.498039 0.498039 0.498039 1.0"/>
      </material>
    </visual>
    <collision>
      <origin xyz="-5.55112e-17 8.67362e-19 0.00249989" rpy="-1.52297e-16 7.23982e-17 -1.5708"/>
      <geometry>
        <mesh filename="package://assets/mirrorm5_80_pulley_03h_52.stl"/>
      </geometry>
    </collision>
  </link>
  <!-- Link cybergear_02b_2 -->
  <link name="cybergear_02b_2">
    <inertial>
      <origin xyz="-0.0673596 -0.000320784 -0.0502102" rpy="0 0 0"/>
      <mass value="0.615532"/>
      <inertia ixx="0.00048956" ixy="-1.39347e-06" ixz="-5.05178e-05" iyy="0.000571369" iyz="-3.86056e-07" izz="0.000521835"/>
    </inertial>
    <!-- Part cybergear_02b_2 -->
    <visual>
      <origin xyz="-0.063 4.55191e-15 -0.0518" rpy="1.5708 -1.5708 0"/>
      <geometry>
        <mesh filename="package://assets/cybergear_02b.stl"/>
      </geometry>
      <material name="cybergear_02b_2_material">
        <color rgba="0.972549 0.529412 0.00392157 1.0"/>
      </material>
    </visual>
    <collision>
      <origin xyz="-0.063 4.55191e-15 -0.0518" rpy="1.5708 -1.5708 0"/>
      <geometry>
        <mesh filename="package://assets/cybergear_02b.stl"/>
      </geometry>
    </collision>
    <!-- Part mirrorsea_spring_mount_05i_hip_yaw -->
    <visual>
      <origin xyz="0 0 -0.0518" rpy="1.5708 1.5708 0"/>
      <geometry>
        <mesh filename="package://assets/mirrorsea_spring_mount_05i_hip_yaw.stl"/>
      </geometry>
      <material name="mirrorsea_spring_mount_05i_hip_yaw_material">
        <color rgba="0.980392 0.713725 0.00392157 1.0"/>
      </material>
    </visual>
    <collision>
      <origin xyz="0 0 -0.0518" rpy="1.5708 1.5708 0"/>
      <geometry>
        <mesh filename="package://assets/mirrorsea_spring_mount_05i_hip_yaw.stl"/>
      </geometry>
    </collision>
    <!-- Part mirrorsea_spring_mount_05i_hip_yaw_2 -->
    <visual>
      <origin xyz="0 4.55191e-15 -0.0518" rpy="1.5708 1.5708 0"/>
      <geometry>
        <mesh filename="package://assets/mirrorsea_spring_mount_05i_hip_yaw__2.stl"/>
      </geometry>
      <material name="mirrorsea_spring_mount_05i_hip_yaw_2_material">
        <color rgba="0.972549 0.529412 0.00392157 1.0"/>
      </material>
    </visual>
    <collision>
      <origin xyz="0 4.55191e-15 -0.0518" rpy="1.5708 1.5708 0"/>
      <geometry>
        <mesh filename="package://assets/mirrorsea_spring_mount_05i_hip_yaw__2.stl"/>
      </geometry>
    </collision>
  </link>
  <!-- Link mirrorsea_humeral_01ka_femoral -->
  <link name="mirrorsea_humeral_01ka_femoral">
    <inertial>
      <origin xyz="0.00513621 -0.023982 -0.135016" rpy="0 0 0"/>
      <mass value="0.60312"/>
      <inertia ixx="0.00238728" ixy="-0.000100328" ixz="0.000213834" iyy="0.00251618" iyz="6.30041e-05" izz="0.00065893"/>
    </inertial>
    <!-- Part mirrorsea_spring_mount_05i_arm_rotation -->
    <visual>
      <origin xyz="0 0 -0.0393" rpy="-4.86161e-16 -1.5708 0"/>
      <geometry>
        <mesh filename="package://assets/mirrorsea_spring_mount_05i_arm_rotation.stl"/>
      </geometry>
      <material name="mirrorsea_spring_mount_05i_arm_rotation_material">
        <color rgba="0.917647 0.917647 0.917647 1.0"/>
      </material>
    </visual>
    <collision>
      <origin xyz="0 0 -0.0393" rpy="-4.86161e-16 -1.5708 0"/>
      <geometry>
        <mesh filename="package://assets/mirrorsea_spring_mount_05i_arm_rotation.stl"/>
      </geometry>
    </collision>
    <!-- Part mirrorsea_humeral_01ka_femoral -->
    <visual>
      <origin xyz="-0.01 -0.0019 -0.2169" rpy="1.5708 -1.15747e-28 -1.5708"/>
      <geometry>
        <mesh filename="package://assets/mirrorsea_humeral_01ka_femoral.stl"/>
      </geometry>
      <material name="mirrorsea_humeral_01ka_femoral_material">
        <color rgba="0.917647 0.917647 0.917647 1.0"/>
      </material>
    </visual>
    <collision>
      <origin xyz="-0.01 -0.0019 -0.2169" rpy="1.5708 -1.15747e-28 -1.5708"/>
      <geometry>
        <mesh filename="package://assets/mirrorsea_humeral_01ka_femoral.stl"/>
      </geometry>
    </collision>
  </link>
  <!-- Link mirrorsea_ankle_02e -->
  <link name="mirrorsea_ankle_02e">
    <inertial>
      <origin xyz="-0.152144 -0.00248491 0.0356485" rpy="0 0 0"/>
      <mass value="0.698336"/>
      <inertia ixx="0.000700512" ixy="-0.000140848" ixz="-0.000302555" iyy="0.00482336" iyz="4.50366e-05" izz="0.00474651"/>
    </inertial>
    <!-- Part mirrorsea_spring_mount_05i_small_knee -->
    <visual>
      <origin xyz="0 0 0.055" rpy="-1.5708 -1.5708 0"/>
      <geometry>
        <mesh filename="package://assets/mirrorsea_spring_mount_05i_small_knee.stl"/>
      </geometry>
      <material name="mirrorsea_spring_mount_05i_small_knee_material">
        <color rgba="0.768627 0.886275 0.952941 1.0"/>
      </material>
    </visual>
    <collision>
      <origin xyz="0 0 0.055" rpy="-1.5708 -1.5708 0"/>
      <geometry>
        <mesh filename="package://assets/mirrorsea_spring_mount_05i_small_knee.stl"/>
      </geometry>
    </collision>
    <!-- Part mirrorsea_ankle_02e -->
    <visual>
      <origin xyz="-0.266 1.56819e-15 0.0516" rpy="1.5708 1.5708 0"/>
      <geometry>
        <mesh filename="package://assets/mirrorsea_ankle_02e.stl"/>
      </geometry>
      <material name="mirrorsea_ankle_02e_material">
        <color rgba="0.231373 0.380392 0.705882 1.0"/>
      </material>
    </visual>
    <collision>
      <origin xyz="-0.266 1.56819e-15 0.0516" rpy="1.5708 1.5708 0"/>
      <geometry>
        <mesh filename="package://assets/mirrorsea_ankle_02e.stl"/>
      </geometry>
    </collision>
  </link>
  <!-- Link mirrorsea_spring_mount_05i_ankle -->
  <link name="mirrorsea_spring_mount_05i_ankle">
    <inertial>
      <origin xyz="-0.0407873 -0.0158098 -0.047479" rpy="0 0 0"/>
      <mass value="0.239095"/>
      <inertia ixx="0.000211088" ixy="3.39872e-05" ixz="-2.54365e-05" iyy="0.000223052" iyz="-6.70887e-06" izz="0.000194"/>
    </inertial>
    <!-- Part mirrorsea_spring_mount_05i_ankle -->
    <visual>
      <origin xyz="0 0 -0.0518" rpy="1.0472 1.5708 0"/>
      <geometry>
        <mesh filename="package://assets/mirrorsea_spring_mount_05i_ankle.stl"/>
      </geometry>
      <material name="mirrorsea_spring_mount_05i_ankle_material">
        <color rgba="0.980392 0.713725 0.00392157 1.0"/>
      </material>
    </visual>
    <collision>
      <origin xyz="0 0 -0.0518" rpy="1.0472 1.5708 0"/>
      <geometry>
        <mesh filename="package://assets/mirrorsea_spring_mount_05i_ankle.stl"/>
      </geometry>
    </collision>
    <!-- Part mirrorsea_spring_mount_05i_ankle_2 -->
    <visual>
      <origin xyz="8.66025e-05 5e-05 -0.0518" rpy="1.0472 1.5708 0"/>
      <geometry>
        <mesh filename="package://assets/mirrorsea_spring_mount_05i_ankle__2.stl"/>
      </geometry>
      <material name="mirrorsea_spring_mount_05i_ankle_2_material">
        <color rgba="0.498039 0.498039 0.498039 1.0"/>
      </material>
    </visual>
    <collision>
      <origin xyz="8.66025e-05 5e-05 -0.0518" rpy="1.0472 1.5708 0"/>
      <geometry>
        <mesh filename="package://assets/mirrorsea_spring_mount_05i_ankle__2.stl"/>
      </geometry>
    </collision>
  </link>
  <!-- Link mirrorheel_04b -->
  <link name="mirrorheel_04b">
    <inertial>
      <origin xyz="-0.0012218 -0.00532959 0.0247941" rpy="0 0 0"/>
      <mass value="0.381619"/>
      <inertia ixx="0.00132368" ixy="1.79052e-05" ixz="-2.3811e-05" iyy="0.00128052" iyz="0.000346286" izz="0.000546573"/>
    </inertial>
    <!-- Part left_foot_heel_collision -->
    <visual>
      <origin xyz="-0.090399 -0.0259668 0.00374903" rpy="-8.53967e-32 -1.0472 -1.5708"/>
      <geometry>
        <mesh filename="package://assets/left_foot_heel_collision.stl"/>
      </geometry>
      <material name="left_foot_heel_collision_material">
        <color rgba="0.615686 0.811765 0.929412 1.0"/>
      </material>
    </visual>
    <collision>
      <origin xyz="-0.090399 -0.0259668 0.00374903" rpy="-8.53967e-32 -1.0472 -1.5708"/>
      <geometry>
        <mesh filename="package://assets/left_foot_heel_collision.stl"/>
      </geometry>
    </collision>
    <!-- Part mirrorheel_04b -->
    <visual>
      <origin xyz="0 -0.0349 0.0432218" rpy="1.0472 -4.26983e-32 -3.14159"/>
      <geometry>
        <mesh filename="package://assets/mirrorheel_04b.stl"/>
      </geometry>
      <material name="mirrorheel_04b_material">
        <color rgba="0.980392 0.713725 0.00392157 1.0"/>
      </material>
    </visual>
    <collision>
      <origin xyz="0 -0.0349 0.0432218" rpy="1.0472 -4.26983e-32 -3.14159"/>
      <geometry>
        <mesh filename="package://assets/mirrorheel_04b.stl"/>
      </geometry>
    </collision>
    <!-- Part mirrorheel_04b_2 -->
    <visual>
      <origin xyz="0 -0.035 0.0432218" rpy="1.0472 -4.26983e-32 -3.14159"/>
      <geometry>
        <mesh filename="package://assets/mirrorheel_04b__2.stl"/>
      </geometry>
      <material name="mirrorheel_04b_2_material">
        <color rgba="0.647059 0.647059 0.647059 1.0"/>
      </material>
    </visual>
    <collision>
      <origin xyz="0 -0.035 0.0432218" rpy="1.0472 -4.26983e-32 -3.14159"/>
      <geometry>
        <mesh filename="package://assets/mirrorheel_04b__2.stl"/>
      </geometry>
    </collision>
    <!-- Part mirrorheel_04b_3 -->
    <visual>
      <origin xyz="0 -0.035 0.0432218" rpy="1.0472 3.84975e-33 3.14159"/>
      <geometry>
        <mesh filename="package://assets/mirrorheel_04b__3.stl"/>
      </geometry>
      <material name="mirrorheel_04b_3_material">
        <color rgba="0.615686 0.811765 0.929412 1.0"/>
      </material>
    </visual>
    <collision>
      <origin xyz="0 -0.035 0.0432218" rpy="1.0472 3.84975e-33 3.14159"/>
      <geometry>
        <mesh filename="package://assets/mirrorheel_04b__3.stl"/>
      </geometry>
    </collision>
  </link>
  <!-- Frame left_foot (dummy link + fixed joint) -->
  <link name="left_foot">
    <origin xyz="0 0 0" rpy="0 -0 0"/>
    <inertial>
      <origin xyz="0 0 0" rpy="0 0 0"/>
      <mass value="1e-9"/>
      <inertia ixx="0" ixy="0" ixz="0" iyy="0" iyz="0" izz="0"/>
    </inertial>
  </link>
  <joint name="left_foot_frame" type="fixed">
    <origin xyz="2.77556e-17 -0.0329533 0.02085" rpy="-8.53967e-32 -1.0472 -1.5708"/>
    <parent link="mirrorheel_04b"/>
    <child link="left_foot"/>
    <axis xyz="0 0 0"/>
  </joint>
  <!-- Link mirrortoes_04b -->
  <link name="mirrortoes_04b">
    <inertial>
      <origin xyz="0.0273127 -0.00913028 -0.0303434" rpy="0 0 0"/>
      <mass value="0.0758634"/>
      <inertia ixx="4.76774e-05" ixy="8.98816e-06" ixz="-4.76652e-06" iyy="7.74597e-05" iyz="1.14421e-06" izz="4.4209e-05"/>
    </inertial>
    <!-- Part mirrortoes_04b -->
    <visual>
      <origin xyz="-0.048 -0.009 -0.0345" rpy="-1.5708 -1.5708 0"/>
      <geometry>
        <mesh filename="package://assets/mirrortoes_04b.stl"/>
      </geometry>
      <material name="mirrortoes_04b_material">
        <color rgba="0.972549 0.529412 0.00392157 1.0"/>
      </material>
    </visual>
    <collision>
      <origin xyz="-0.048 -0.009 -0.0345" rpy="-1.5708 -1.5708 0"/>
      <geometry>
        <mesh filename="package://assets/mirrortoes_04b.stl"/>
      </geometry>
    </collision>
    <!-- Part mirrortoes_04b_2 -->
    <visual>
      <origin xyz="-0.048 -0.009 -0.0344" rpy="-1.5708 -1.5708 0"/>
      <geometry>
        <mesh filename="package://assets/mirrortoes_04b__2.stl"/>
      </geometry>
      <material name="mirrortoes_04b_2_material">
        <color rgba="0.768627 0.886275 0.952941 1.0"/>
      </material>
    </visual>
    <collision>
      <origin xyz="-0.048 -0.009 -0.0344" rpy="-1.5708 -1.5708 0"/>
      <geometry>
        <mesh filename="package://assets/mirrortoes_04b__2.stl"/>
      </geometry>
    </collision>
    <!-- Part left_foot_toe_collision -->
    <visual>
      <origin xyz="-0.0863267 -0.021 0.0566129" rpy="-1.5708 -2.07604e-17 0"/>
      <geometry>
        <mesh filename="package://assets/left_foot_toe_collision.stl"/>
      </geometry>
      <material name="left_foot_toe_collision_material">
        <color rgba="0.647059 0.647059 0.647059 1.0"/>
      </material>
    </visual>
    <collision>
      <origin xyz="-0.0863267 -0.021 0.0566129" rpy="-1.5708 -2.07604e-17 0"/>
      <geometry>
        <mesh filename="package://assets/left_foot_toe_collision.stl"/>
      </geometry>
    </collision>
    <!-- Part mirrortoes_04b_3 -->
    <visual>
      <origin xyz="-0.048 -0.009 -0.0343" rpy="-1.5708 -1.5708 0"/>
      <geometry>
        <mesh filename="package://assets/mirrortoes_04b__3.stl"/>
      </geometry>
      <material name="mirrortoes_04b_3_material">
        <color rgba="0.498039 0.498039 0.498039 1.0"/>
      </material>
    </visual>
    <collision>
      <origin xyz="-0.048 -0.009 -0.0343" rpy="-1.5708 -1.5708 0"/>
      <geometry>
        <mesh filename="package://assets/mirrortoes_04b__3.stl"/>
      </geometry>
    </collision>
  </link>
  <!-- Joint from mirrorheel_04b to mirrortoes_04b -->
  <joint name="left_toe" type="revolute">
    <origin xyz="-0.0345 -0.0511058 0.089291" rpy="1.5708 -1.0472 -1.5708"/>
    <parent link="mirrorheel_04b"/>
    <child link="mirrortoes_04b"/>
    <axis xyz="0 0 1"/>
    <limit effort="10" velocity="10" lower="-3.141592653589793" upper="3.141592653589793"/>
  </joint>
  <!-- Joint from mirrorsea_spring_mount_05i_ankle to mirrorheel_04b -->
  <joint name="left_ankle_roll" type="revolute">
    <origin xyz="-0.078807 0.0126977 -0.0518" rpy="1.0472 1.5708 0"/>
    <parent link="mirrorsea_spring_mount_05i_ankle"/>
    <child link="mirrorheel_04b"/>
    <axis xyz="0 0 1"/>
    <limit effort="10" velocity="10" lower="-3.141592653589793" upper="3.141592653589793"/>
  </joint>
  <!-- Joint from mirrorsea_ankle_02e to mirrorsea_spring_mount_05i_ankle -->
  <joint name="left_ankle_pitch" type="revolute">
    <origin xyz="-0.266 1.56299e-15 -0.0021" rpy="3.14159 1.51721e-16 -2.43505e-15"/>
    <parent link="mirrorsea_ankle_02e"/>
    <child link="mirrorsea_spring_mount_05i_ankle"/>
    <axis xyz="0 0 1"/>
    <limit effort="10" velocity="10" lower="-3.141592653589793" upper="3.141592653589793"/>
  </joint>
  <!-- Joint from mirrorsea_humeral_01ka_femoral to mirrorsea_ankle_02e -->
  <joint name="left_knee" type="revolute">
    <origin xyz="-0.01 -0.0586 -0.2169" rpy="-1.5708 -1.5708 0"/>
    <parent link="mirrorsea_humeral_01ka_femoral"/>
    <child link="mirrorsea_ankle_02e"/>
    <axis xyz="0 0 1"/>
    <limit effort="10" velocity="10" lower="-3.141592653589793" upper="3.141592653589793"/>
  </joint>
  <!-- Joint from cybergear_02b_2 to mirrorsea_humeral_01ka_femoral -->
  <joint name="left_hip_yaw" type="revolute">
    <origin xyz="-0.0962 4.55191e-15 -0.0518" rpy="3.14159 -1.5708 0"/>
    <parent link="cybergear_02b_2"/>
    <child link="mirrorsea_humeral_01ka_femoral"/>
    <axis xyz="0 0 1"/>
    <limit effort="10" velocity="10" lower="-3.141592653589793" upper="3.141592653589793"/>
  </joint>
  <!-- Joint from mirrorm5_80_pulley_03h_52 to cybergear_02b_2 -->
  <joint name="left_hip_roll" type="revolute">
    <origin xyz="-5.55112e-17 -0.052 -0.0725001" rpy="1.5708 0.0872665 6.37186e-32"/>
    <parent link="mirrorm5_80_pulley_03h_52"/>
    <child link="cybergear_02b_2"/>
    <axis xyz="0 0 1"/>
    <limit effort="10" velocity="10" lower="-3.141592653589793" upper="3.141592653589793"/>
  </joint>
  <!-- Joint from pelvis_08 to mirrorm5_80_pulley_03h_52 -->
  <joint name="left_hip_pitch" type="revolute">
    <origin xyz="-0.126339 0 -0.0568402" rpy="2.0678e-47 -0.0872665 6.29718e-34"/>
    <parent link="pelvis_08"/>
    <child link="mirrorm5_80_pulley_03h_52"/>
    <axis xyz="0 0 1"/>
    <limit effort="10" velocity="10" lower="-3.141592653589793" upper="3.141592653589793"/>
  </joint>
  <!-- Joint from torso_pitch_yaw_03 to pelvis_08 -->
  <joint name="torso_pitch" type="revolute">
    <origin xyz="6.10623e-16 -1.22189e-17 -0.068" rpy="-1.5708 -3.62679e-32 6.5562e-17"/>
    <parent link="torso_pitch_yaw_03"/>
    <child link="pelvis_08"/>
    <axis xyz="0 0 1"/>
    <limit effort="10" velocity="10" lower="-3.141592653589793" upper="3.141592653589793"/>
  </joint>
  <!-- Joint from waist_04d to torso_pitch_yaw_03 -->
  <joint name="torso_roll" type="revolute">
    <origin xyz="-0.000527364 0.069998 0.296" rpy="-1.57833 1.5708 0"/>
    <parent link="waist_04d"/>
    <child link="torso_pitch_yaw_03"/>
    <axis xyz="0 0 1"/>
    <limit effort="10" velocity="10" lower="-3.141592653589793" upper="3.141592653589793"/>
  </joint>
  <!-- Joint from thorax_02d to waist_04d -->
  <joint name="torso_yaw" type="revolute">
    <origin xyz="9.37011e-19 -4.16241e-17 -0.015" rpy="3.14159 -2.20235e-23 1.57833"/>
    <parent link="thorax_02d"/>
    <child link="waist_04d"/>
    <axis xyz="0 0 1"/>
    <limit effort="10" velocity="10" lower="-3.141592653589793" upper="3.141592653589793"/>
  </joint>
  <!-- Link hl_shoulder_yaw_03a -->
  <link name="hl_shoulder_yaw_03a">
    <inertial>
      <origin xyz="-0.000431902 -0.000146853 -0.0273848" rpy="0 0 0"/>
      <mass value="0.176309"/>
      <inertia ixx="0.000130995" ixy="4.81528e-07" ixz="5.7942e-07" iyy="0.000105595" iyz="2.61245e-07" izz="0.000149717"/>
    </inertial>
    <!-- Part hl_shoulder_pitch_roller_clip_03a -->
    <visual>
      <origin xyz="-1.35174e-05 7.80626e-17 -0.0214" rpy="-1.0842e-16 -7.84266e-17 -1.5708"/>
      <geometry>
        <mesh filename="package://assets/hl_shoulder_pitch_roller_clip_03a.stl"/>
      </geometry>
      <material name="hl_shoulder_pitch_roller_clip_03a_material">
        <color rgba="0.972549 0.529412 0.00392157 1.0"/>
      </material>
    </visual>
    <collision>
      <origin xyz="-1.35174e-05 7.80626e-17 -0.0214" rpy="-1.0842e-16 -7.84266e-17 -1.5708"/>
      <geometry>
        <mesh filename="package://assets/hl_shoulder_pitch_roller_clip_03a.stl"/>
      </geometry>
    </collision>
    <!-- Part hl_shoulder_pitch_roller_clip_03a_2 -->
    <visual>
      <origin xyz="-1.35174e-05 -0.0002 -0.0214" rpy="-1.10699e-15 -1.74261e-16 -1.5708"/>
      <geometry>
        <mesh filename="package://assets/hl_shoulder_pitch_roller_clip_03a__2.stl"/>
      </geometry>
      <material name="hl_shoulder_pitch_roller_clip_03a_2_material">
        <color rgba="0.980392 0.713725 0.00392157 1.0"/>
      </material>
    </visual>
    <collision>
      <origin xyz="-1.35174e-05 -0.0002 -0.0214" rpy="-1.10699e-15 -1.74261e-16 -1.5708"/>
      <geometry>
        <mesh filename="package://assets/hl_shoulder_pitch_roller_clip_03a__2.stl"/>
      </geometry>
    </collision>
    <!-- Part hl_shoulder_yaw_03a -->
    <visual>
      <origin xyz="0.012 0 0" rpy="-1.5708 3.44412e-33 1.29358e-31"/>
      <geometry>
        <mesh filename="package://assets/hl_shoulder_yaw_03a.stl"/>
      </geometry>
      <material name="hl_shoulder_yaw_03a_material">
        <color rgba="0.615686 0.811765 0.929412 1.0"/>
      </material>
    </visual>
    <collision>
      <origin xyz="0.012 0 0" rpy="-1.5708 3.44412e-33 1.29358e-31"/>
      <geometry>
        <mesh filename="package://assets/hl_shoulder_yaw_03a.stl"/>
      </geometry>
    </collision>
    <!-- Part hl_shoulder_pitch_roller_clip_03a_3 -->
    <visual>
      <origin xyz="-1.35174e-05 -3.46945e-18 -0.0214" rpy="-2.72642e-16 -1.47641e-16 -1.5708"/>
      <geometry>
        <mesh filename="package://assets/hl_shoulder_pitch_roller_clip_03a__3.stl"/>
      </geometry>
      <material name="hl_shoulder_pitch_roller_clip_03a_3_material">
        <color rgba="0.768627 0.886275 0.952941 1.0"/>
      </material>
    </visual>
    <collision>
      <origin xyz="-1.35174e-05 -3.46945e-18 -0.0214" rpy="-2.72642e-16 -1.47641e-16 -1.5708"/>
      <geometry>
        <mesh filename="package://assets/hl_shoulder_pitch_roller_clip_03a__3.stl"/>
      </geometry>
    </collision>
    <!-- Part hl_shoulder_pitch_roller_clip_03a_4 -->
    <visual>
      <origin xyz="-1.35174e-05 0.0002 -0.0214" rpy="-2.96715e-31 -6.46362e-17 -1.5708"/>
      <geometry>
        <mesh filename="package://assets/hl_shoulder_pitch_roller_clip_03a__4.stl"/>
      </geometry>
      <material name="hl_shoulder_pitch_roller_clip_03a_4_material">
        <color rgba="0.498039 0.498039 0.498039 1.0"/>
      </material>
    </visual>
    <collision>
      <origin xyz="-1.35174e-05 0.0002 -0.0214" rpy="-2.96715e-31 -6.46362e-17 -1.5708"/>
      <geometry>
        <mesh filename="package://assets/hl_shoulder_pitch_roller_clip_03a__4.stl"/>
      </geometry>
    </collision>
  </link>
  <!-- Link hl_humeral_03a -->
  <link name="hl_humeral_03a">
    <inertial>
      <origin xyz="-0.0714633 0.00178243 -0.0373091" rpy="0 0 0"/>
      <mass value="0.332565"/>
      <inertia ixx="0.000218226" ixy="-1.6259e-05" ixz="6.79165e-05" iyy="0.000540858" iyz="5.42911e-06" izz="0.000482877"/>
    </inertial>
    <!-- Part hl_humeral_03a -->
    <visual>
      <origin xyz="-1.11022e-15 -5e-05 -0.0402" rpy="-5.96454e-18 2.18514e-18 -5.3259e-18"/>
      <geometry>
        <mesh filename="package://assets/hl_humeral_03a.stl"/>
      </geometry>
      <material name="hl_humeral_03a_material">
        <color rgba="0.615686 0.811765 0.929412 1.0"/>
      </material>
    </visual>
    <collision>
      <origin xyz="-1.11022e-15 -5e-05 -0.0402" rpy="-5.96454e-18 2.18514e-18 -5.3259e-18"/>
      <geometry>
        <mesh filename="package://assets/hl_humeral_03a.stl"/>
      </geometry>
    </collision>
    <!-- Part hl_humeral_03a_2 -->
    <visual>
      <origin xyz="0 0 -0.0402" rpy="-1.60964e-17 -2.72646e-32 -1.22821e-31"/>
      <geometry>
        <mesh filename="package://assets/hl_humeral_03a__2.stl"/>
      </geometry>
      <material name="hl_humeral_03a_2_material">
        <color rgba="0.647059 0.647059 0.647059 1.0"/>
      </material>
    </visual>
    <collision>
      <origin xyz="0 0 -0.0402" rpy="-1.60964e-17 -2.72646e-32 -1.22821e-31"/>
      <geometry>
        <mesh filename="package://assets/hl_humeral_03a__2.stl"/>
      </geometry>
    </collision>
    <!-- Part hl_humeral_03a_3 -->
    <visual>
      <origin xyz="-1.38778e-17 -0.0001 -0.0402" rpy="-1.60964e-17 -2.00719e-32 1.54439e-18"/>
      <geometry>
        <mesh filename="package://assets/hl_humeral_03a__3.stl"/>
      </geometry>
      <material name="hl_humeral_03a_3_material">
        <color rgba="0.231373 0.380392 0.705882 1.0"/>
      </material>
    </visual>
    <collision>
      <origin xyz="-1.38778e-17 -0.0001 -0.0402" rpy="-1.60964e-17 -2.00719e-32 1.54439e-18"/>
      <geometry>
        <mesh filename="package://assets/hl_humeral_03a__3.stl"/>
      </geometry>
    </collision>
  </link>
  <!-- Link hl_hum_elbow_03 -->
  <link name="hl_hum_elbow_03">
    <inertial>
      <origin xyz="0.00122377 -0.0029525 -0.0191756" rpy="0 0 0"/>
      <mass value="0.130391"/>
      <inertia ixx="0.000209536" ixy="8.24276e-06" ixz="7.13689e-05" iyy="0.000249745" iyz="-1.28557e-05" izz="9.75661e-05"/>
    </inertial>
    <!-- Part hl_hum_elbow_03 -->
    <visual>
      <origin xyz="0.012 2.77556e-17 0.0464" rpy="-1.5708 -0 1.74115e-17"/>
      <geometry>
        <mesh filename="package://assets/hl_hum_elbow_03.stl"/>
      </geometry>
      <material name="hl_hum_elbow_03_material">
        <color rgba="0.498039 0.498039 0.498039 1.0"/>
      </material>
    </visual>
    <collision>
      <origin xyz="0.012 2.77556e-17 0.0464" rpy="-1.5708 -0 1.74115e-17"/>
      <geometry>
        <mesh filename="package://assets/hl_hum_elbow_03.stl"/>
      </geometry>
    </collision>
    <!-- Part hl_hum_elbow_03_2 -->
    <visual>
      <origin xyz="0.012 2.77556e-17 0.0464" rpy="-1.5708 -0 1.74115e-17"/>
      <geometry>
        <mesh filename="package://assets/hl_hum_elbow_03__2.stl"/>
      </geometry>
      <material name="hl_hum_elbow_03_2_material">
        <color rgba="0.980392 0.713725 0.00392157 1.0"/>
      </material>
    </visual>
    <collision>
      <origin xyz="0.012 2.77556e-17 0.0464" rpy="-1.5708 -0 1.74115e-17"/>
      <geometry>
        <mesh filename="package://assets/hl_hum_elbow_03__2.stl"/>
      </geometry>
    </collision>
    <!-- Part hl_hum_elbow_03_3 -->
    <visual>
      <origin xyz="0.012 2.77556e-17 0.0464" rpy="-1.5708 -0 1.74115e-17"/>
      <geometry>
        <mesh filename="package://assets/hl_hum_elbow_03__3.stl"/>
      </geometry>
      <material name="hl_hum_elbow_03_3_material">
        <color rgba="0.972549 0.529412 0.00392157 1.0"/>
      </material>
    </visual>
    <collision>
      <origin xyz="0.012 2.77556e-17 0.0464" rpy="-1.5708 -0 1.74115e-17"/>
      <geometry>
        <mesh filename="package://assets/hl_hum_elbow_03__3.stl"/>
      </geometry>
    </collision>
  </link>
  <!-- Link hl_prox_forearm_03e -->
  <link name="hl_prox_forearm_03e">
    <inertial>
      <origin xyz="-0.0388066 0.00093388 -0.0356244" rpy="0 0 0"/>
      <mass value="0.116863"/>
      <inertia ixx="8.81194e-05" ixy="1.73856e-06" ixz="5.87523e-06" iyy="0.000105215" iyz="-3.50772e-06" izz="9.20621e-05"/>
    </inertial>
    <!-- Part hl_prox_forearm_03e -->
    <visual>
      <origin xyz="-2.77556e-17 1.73472e-17 -0.0343" rpy="-3.14159 8.68785e-16 6.46773e-16"/>
      <geometry>
        <mesh filename="package://assets/hl_prox_forearm_03e.stl"/>
      </geometry>
      <material name="hl_prox_forearm_03e_material">
        <color rgba="0.972549 0.529412 0.00392157 1.0"/>
      </material>
    </visual>
    <collision>
      <origin xyz="-2.77556e-17 1.73472e-17 -0.0343" rpy="-3.14159 8.68785e-16 6.46773e-16"/>
      <geometry>
        <mesh filename="package://assets/hl_prox_forearm_03e.stl"/>
      </geometry>
    </collision>
    <!-- Part hl_prox_forearm_03e_2 -->
    <visual>
      <origin xyz="8.32667e-17 1.38778e-17 -0.0343" rpy="-3.14159 7.49642e-16 6.46773e-16"/>
      <geometry>
        <mesh filename="package://assets/hl_prox_forearm_03e__2.stl"/>
      </geometry>
      <material name="hl_prox_forearm_03e_2_material">
        <color rgba="0.498039 0.498039 0.498039 1.0"/>
      </material>
    </visual>
    <collision>
      <origin xyz="8.32667e-17 1.38778e-17 -0.0343" rpy="-3.14159 7.49642e-16 6.46773e-16"/>
      <geometry>
        <mesh filename="package://assets/hl_prox_forearm_03e__2.stl"/>
      </geometry>
    </collision>
    <!-- Part hl_prox_forearm_03e_3 -->
    <visual>
      <origin xyz="8.32667e-17 6.93889e-18 -0.0342" rpy="-3.14159 8.68785e-16 6.50682e-16"/>
      <geometry>
        <mesh filename="package://assets/hl_prox_forearm_03e__3.stl"/>
      </geometry>
      <material name="hl_prox_forearm_03e_3_material">
        <color rgba="0.615686 0.811765 0.929412 1.0"/>
      </material>
    </visual>
    <collision>
      <origin xyz="8.32667e-17 6.93889e-18 -0.0342" rpy="-3.14159 8.68785e-16 6.50682e-16"/>
      <geometry>
        <mesh filename="package://assets/hl_prox_forearm_03e__3.stl"/>
      </geometry>
    </collision>
    <!-- Part hl_prox_forearm_03e_4 -->
    <visual>
      <origin xyz="2.77556e-17 0 -0.0344" rpy="-3.14159 -0 -9.86076e-32"/>
      <geometry>
        <mesh filename="package://assets/hl_prox_forearm_03e__4.stl"/>
      </geometry>
      <material name="hl_prox_forearm_03e_4_material">
        <color rgba="0.980392 0.713725 0.00392157 1.0"/>
      </material>
    </visual>
    <collision>
      <origin xyz="2.77556e-17 0 -0.0344" rpy="-3.14159 -0 -9.86076e-32"/>
      <geometry>
        <mesh filename="package://assets/hl_prox_forearm_03e__4.stl"/>
      </geometry>
    </collision>
  </link>
  <!-- Link mirrorhl_fore_arm_02c_part_01j -->
  <link name="mirrorhl_fore_arm_02c_part_01j">
    <inertial>
      <origin xyz="-0.00140023 -0.00320089 -0.0425478" rpy="0 0 0"/>
      <mass value="0.0971947"/>
      <inertia ixx="8.35223e-05" ixy="-1.88484e-07" ixz="-1.65232e-06" iyy="7.77236e-05" iyz="-2.93001e-06" izz="6.6518e-05"/>
    </inertial>
    <!-- Part mirrorhl_fore_arm_02c_part_01j -->
    <visual>
      <origin xyz="-0.0491308 -0.110857 0.285457" rpy="-0.378919 -1.37372 -7.52587e-16"/>
      <geometry>
        <mesh filename="package://assets/mirrorhl_fore_arm_02c_part_01j.stl"/>
      </geometry>
      <material name="mirrorhl_fore_arm_02c_part_01j_material">
        <color rgba="0.498039 0.498039 0.498039 1.0"/>
      </material>
    </visual>
    <collision>
      <origin xyz="-0.0491308 -0.110857 0.285457" rpy="-0.378919 -1.37372 -7.52587e-16"/>
      <geometry>
        <mesh filename="package://assets/mirrorhl_fore_arm_02c_part_01j.stl"/>
      </geometry>
    </collision>
    <!-- Part mirrorhl_fore_arm_02c_part_01j_2 -->
    <visual>
      <origin xyz="-0.049131 -0.110858 0.285457" rpy="-0.378919 -1.37372 -3.03748e-17"/>
      <geometry>
        <mesh filename="package://assets/mirrorhl_fore_arm_02c_part_01j__2.stl"/>
      </geometry>
      <material name="mirrorhl_fore_arm_02c_part_01j_2_material">
        <color rgba="0.980392 0.713725 0.00392157 1.0"/>
      </material>
    </visual>
    <collision>
      <origin xyz="-0.049131 -0.110858 0.285457" rpy="-0.378919 -1.37372 -3.03748e-17"/>
      <geometry>
        <mesh filename="package://assets/mirrorhl_fore_arm_02c_part_01j__2.stl"/>
      </geometry>
    </collision>
  </link>
  <!-- Joint from hl_prox_forearm_03e to mirrorhl_fore_arm_02c_part_01j -->
  <joint name="right_forearm_yaw" type="revolute">
    <origin xyz="-0.06438 -2.77556e-17 -0.0343" rpy="1.5708 -7.77801e-16 1.5708"/>
    <parent link="hl_prox_forearm_03e"/>
    <child link="mirrorhl_fore_arm_02c_part_01j"/>
    <axis xyz="0 0 1"/>
    <limit effort="10" velocity="10" lower="-3.141592653589793" upper="3.141592653589793"/>
  </joint>
  <!-- Joint from hl_hum_elbow_03 to hl_prox_forearm_03e -->
  <joint name="right_elbow_pitch" type="revolute">
    <origin xyz="0.0382 -0.0324 -0.056" rpy="1.5708 -1.5708 0"/>
    <parent link="hl_hum_elbow_03"/>
    <child link="hl_prox_forearm_03e"/>
    <axis xyz="0 0 1"/>
    <limit effort="10" velocity="10" lower="-3.141592653589793" upper="3.141592653589793"/>
  </joint>
  <!-- Joint from hl_humeral_03a to hl_hum_elbow_03 -->
  <joint name="right_elbow_yaw" type="revolute">
    <origin xyz="-0.1438 -5e-05 -0.0407565" rpy="1.5708 -1.56326 1.5708"/>
    <parent link="hl_humeral_03a"/>
    <child link="hl_hum_elbow_03"/>
    <axis xyz="0 0 1"/>
    <limit effort="10" velocity="10" lower="-3.141592653589793" upper="3.141592653589793"/>
  </joint>
  <!-- Joint from hl_shoulder_yaw_03a to hl_humeral_03a -->
  <joint name="right_shoulder_roll" type="revolute">
    <origin xyz="-1.35174e-05 0.04015 -0.0556" rpy="-1.5708 1.10699e-15 -1.90372e-15"/>
    <parent link="hl_shoulder_yaw_03a"/>
    <child link="hl_humeral_03a"/>
    <axis xyz="0 0 1"/>
    <limit effort="10" velocity="10" lower="-3.141592653589793" upper="3.141592653589793"/>
  </joint>
  <!-- Joint from thorax_02d to hl_shoulder_yaw_03a -->
  <joint name="right_shoulder_pitch" type="revolute">
    <origin xyz="0.00694291 -0.150862 -0.0258308" rpy="-1.45854 -1.5708 0"/>
    <parent link="thorax_02d"/>
    <child link="hl_shoulder_yaw_03a"/>
    <axis xyz="0 0 1"/>
    <limit effort="10" velocity="10" lower="-3.141592653589793" upper="3.141592653589793"/>
  </joint>
  <!-- Link mirrorhl_shoulder_yaw_03a -->
  <link name="mirrorhl_shoulder_yaw_03a">
    <inertial>
      <origin xyz="0.000146801 0.000431893 -0.00318482" rpy="0 0 0"/>
      <mass value="0.176309"/>
      <inertia ixx="0.000105595" ixy="4.81482e-07" ixz="-2.61516e-07" iyy="0.000130995" iyz="-5.79432e-07" izz="0.000149716"/>
    </inertial>
    <!-- Part mirrorhl_shoulder_yaw_03a -->
    <visual>
      <origin xyz="-5.55112e-16 -0.012 0.0242" rpy="-1.5708 1.31139e-17 -1.5708"/>
      <geometry>
        <mesh filename="package://assets/mirrorhl_shoulder_yaw_03a.stl"/>
      </geometry>
      <material name="mirrorhl_shoulder_yaw_03a_material">
        <color rgba="0.498039 0.498039 0.498039 1.0"/>
      </material>
    </visual>
    <collision>
      <origin xyz="-5.55112e-16 -0.012 0.0242" rpy="-1.5708 1.31139e-17 -1.5708"/>
      <geometry>
        <mesh filename="package://assets/mirrorhl_shoulder_yaw_03a.stl"/>
      </geometry>
    </collision>
    <!-- Part mirrorhl_shoulder_pitch_roller_clip_03a -->
    <visual>
      <origin xyz="1.21431e-17 1.35174e-05 0.0028" rpy="3.14159 -6.21646e-17 -4.67953e-14"/>
      <geometry>
        <mesh filename="package://assets/mirrorhl_shoulder_pitch_roller_clip_03a.stl"/>
      </geometry>
      <material name="mirrorhl_shoulder_pitch_roller_clip_03a_material">
        <color rgba="0.647059 0.647059 0.647059 1.0"/>
      </material>
    </visual>
    <collision>
      <origin xyz="1.21431e-17 1.35174e-05 0.0028" rpy="3.14159 -6.21646e-17 -4.67953e-14"/>
      <geometry>
        <mesh filename="package://assets/mirrorhl_shoulder_pitch_roller_clip_03a.stl"/>
      </geometry>
    </collision>
    <!-- Part mirrorhl_shoulder_pitch_roller_clip_03a_2 -->
    <visual>
      <origin xyz="5.37764e-17 1.35174e-05 0.0028" rpy="3.14159 7.66788e-17 -4.68365e-14"/>
      <geometry>
        <mesh filename="package://assets/mirrorhl_shoulder_pitch_roller_clip_03a__2.stl"/>
      </geometry>
      <material name="mirrorhl_shoulder_pitch_roller_clip_03a_2_material">
        <color rgba="0.231373 0.380392 0.705882 1.0"/>
      </material>
    </visual>
    <collision>
      <origin xyz="5.37764e-17 1.35174e-05 0.0028" rpy="3.14159 7.66788e-17 -4.68365e-14"/>
      <geometry>
        <mesh filename="package://assets/mirrorhl_shoulder_pitch_roller_clip_03a__2.stl"/>
      </geometry>
    </collision>
    <!-- Part mirrorhl_shoulder_pitch_roller_clip_03a_3 -->
    <visual>
      <origin xyz="-0.0002 1.35174e-05 0.0028" rpy="3.14159 6.24735e-17 -4.70709e-14"/>
      <geometry>
        <mesh filename="package://assets/mirrorhl_shoulder_pitch_roller_clip_03a__3.stl"/>
      </geometry>
      <material name="mirrorhl_shoulder_pitch_roller_clip_03a_3_material">
        <color rgba="0.768627 0.886275 0.952941 1.0"/>
      </material>
    </visual>
    <collision>
      <origin xyz="-0.0002 1.35174e-05 0.0028" rpy="3.14159 6.24735e-17 -4.70709e-14"/>
      <geometry>
        <mesh filename="package://assets/mirrorhl_shoulder_pitch_roller_clip_03a__3.stl"/>
      </geometry>
    </collision>
    <!-- Part mirrorhl_shoulder_pitch_roller_clip_03a_4 -->
    <visual>
      <origin xyz="0.0002 1.35174e-05 0.0028" rpy="3.14159 7.68097e-17 -4.65183e-14"/>
      <geometry>
        <mesh filename="package://assets/mirrorhl_shoulder_pitch_roller_clip_03a__4.stl"/>
      </geometry>
      <material name="mirrorhl_shoulder_pitch_roller_clip_03a_4_material">
        <color rgba="0.917647 0.917647 0.917647 1.0"/>
      </material>
    </visual>
    <collision>
      <origin xyz="0.0002 1.35174e-05 0.0028" rpy="3.14159 7.68097e-17 -4.65183e-14"/>
      <geometry>
        <mesh filename="package://assets/mirrorhl_shoulder_pitch_roller_clip_03a__4.stl"/>
      </geometry>
    </collision>
  </link>
  <!-- Link mirrorhl_humeral_03a -->
  <link name="mirrorhl_humeral_03a">
    <inertial>
      <origin xyz="-0.0714631 0.00181679 0.0374596" rpy="0 0 0"/>
      <mass value="0.332573"/>
      <inertia ixx="0.000218624" ixy="-1.62647e-05" ixz="-6.79083e-05" iyy="0.000540855" iyz="-5.43313e-06" izz="0.000483269"/>
    </inertial>
    <!-- Part mirrorhl_humeral_03a -->
    <visual>
      <origin xyz="3.46945e-18 -5e-05 0.04035" rpy="-5.96985e-16 1.65543e-16 -3.85886e-16"/>
      <geometry>
        <mesh filename="package://assets/mirrorhl_humeral_03a.stl"/>
      </geometry>
      <material name="mirrorhl_humeral_03a_material">
        <color rgba="0.972549 0.529412 0.00392157 1.0"/>
      </material>
    </visual>
    <collision>
      <origin xyz="3.46945e-18 -5e-05 0.04035" rpy="-5.96985e-16 1.65543e-16 -3.85886e-16"/>
      <geometry>
        <mesh filename="package://assets/mirrorhl_humeral_03a.stl"/>
      </geometry>
    </collision>
    <!-- Part mirrorhl_humeral_03a_2 -->
    <visual>
      <origin xyz="3.46945e-18 0 0.04035" rpy="-6.02871e-16 1.65543e-16 -3.85886e-16"/>
      <geometry>
        <mesh filename="package://assets/mirrorhl_humeral_03a__2.stl"/>
      </geometry>
      <material name="mirrorhl_humeral_03a_2_material">
        <color rgba="0.498039 0.498039 0.498039 1.0"/>
      </material>
    </visual>
    <collision>
      <origin xyz="3.46945e-18 0 0.04035" rpy="-6.02871e-16 1.65543e-16 -3.85886e-16"/>
      <geometry>
        <mesh filename="package://assets/mirrorhl_humeral_03a__2.stl"/>
      </geometry>
    </collision>
    <!-- Part mirrorhl_humeral_03a_3 -->
    <visual>
      <origin xyz="3.46945e-18 5.55112e-17 0.04035" rpy="-5.96985e-16 1.71446e-16 -3.43614e-16"/>
      <geometry>
        <mesh filename="package://assets/mirrorhl_humeral_03a__3.stl"/>
      </geometry>
      <material name="mirrorhl_humeral_03a_3_material">
        <color rgba="0.980392 0.713725 0.00392157 1.0"/>
      </material>
    </visual>
    <collision>
      <origin xyz="3.46945e-18 5.55112e-17 0.04035" rpy="-5.96985e-16 1.71446e-16 -3.43614e-16"/>
      <geometry>
        <mesh filename="package://assets/mirrorhl_humeral_03a__3.stl"/>
      </geometry>
    </collision>
  </link>
  <!-- Link mirrorhl_hum_elbow_03 -->
  <link name="mirrorhl_hum_elbow_03">
    <inertial>
      <origin xyz="0.00122338 0.00295337 -0.0191753" rpy="0 0 0"/>
      <mass value="0.130399"/>
      <inertia ixx="0.000209541" ixy="-8.24153e-06" ixz="7.13706e-05" iyy="0.00024975" iyz="1.28552e-05" izz="9.7572e-05"/>
    </inertial>
    <!-- Part mirrorhl_hum_elbow_03 -->
    <visual>
      <origin xyz="0.012 0 0.0464" rpy="-1.5708 -0 -2.68164e-18"/>
      <geometry>
        <mesh filename="package://assets/mirrorhl_hum_elbow_03.stl"/>
      </geometry>
      <material name="mirrorhl_hum_elbow_03_material">
        <color rgba="0.647059 0.647059 0.647059 1.0"/>
      </material>
    </visual>
    <collision>
      <origin xyz="0.012 0 0.0464" rpy="-1.5708 -0 -2.68164e-18"/>
      <geometry>
        <mesh filename="package://assets/mirrorhl_hum_elbow_03.stl"/>
      </geometry>
    </collision>
    <!-- Part mirrorhl_hum_elbow_03_2 -->
    <visual>
      <origin xyz="0.012 0 0.0464" rpy="-1.5708 -0 -2.68164e-18"/>
      <geometry>
        <mesh filename="package://assets/mirrorhl_hum_elbow_03__2.stl"/>
      </geometry>
      <material name="mirrorhl_hum_elbow_03_2_material">
        <color rgba="0.768627 0.886275 0.952941 1.0"/>
      </material>
    </visual>
    <collision>
      <origin xyz="0.012 0 0.0464" rpy="-1.5708 -0 -2.68164e-18"/>
      <geometry>
        <mesh filename="package://assets/mirrorhl_hum_elbow_03__2.stl"/>
      </geometry>
    </collision>
    <!-- Part mirrorhl_hum_elbow_03_3 -->
    <visual>
      <origin xyz="0.012 0 0.0464" rpy="-1.5708 -0 -3.21381e-18"/>
      <geometry>
        <mesh filename="package://assets/mirrorhl_hum_elbow_03__3.stl"/>
      </geometry>
      <material name="mirrorhl_hum_elbow_03_3_material">
        <color rgba="0.231373 0.380392 0.705882 1.0"/>
      </material>
    </visual>
    <collision>
      <origin xyz="0.012 0 0.0464" rpy="-1.5708 -0 -3.21381e-18"/>
      <geometry>
        <mesh filename="package://assets/mirrorhl_hum_elbow_03__3.stl"/>
      </geometry>
    </collision>
  </link>
  <!-- Link mirrorhl_prox_forearm_03e -->
  <link name="mirrorhl_prox_forearm_03e">
    <inertial>
      <origin xyz="-0.0388065 -0.000933941 -0.0356243" rpy="0 0 0"/>
      <mass value="0.116864"/>
      <inertia ixx="8.812e-05" ixy="-1.7386e-06" ixz="5.87522e-06" iyy="0.000105215" iyz="3.50769e-06" izz="9.20626e-05"/>
    </inertial>
    <!-- Part mirrorhl_prox_forearm_03e -->
    <visual>
      <origin xyz="0 4.51028e-17 -0.0343" rpy="-2.68087e-16 -2.03732e-16 4.61504e-18"/>
      <geometry>
        <mesh filename="package://assets/mirrorhl_prox_forearm_03e.stl"/>
      </geometry>
      <material name="mirrorhl_prox_forearm_03e_material">
        <color rgba="0.917647 0.917647 0.917647 1.0"/>
      </material>
    </visual>
    <collision>
      <origin xyz="0 4.51028e-17 -0.0343" rpy="-2.68087e-16 -2.03732e-16 4.61504e-18"/>
      <geometry>
        <mesh filename="package://assets/mirrorhl_prox_forearm_03e.stl"/>
      </geometry>
    </collision>
    <!-- Part mirrorhl_prox_forearm_03e_2 -->
    <visual>
      <origin xyz="5.55112e-17 4.85723e-17 -0.0342" rpy="-2.54286e-16 -8.45886e-17 4.61504e-18"/>
      <geometry>
        <mesh filename="package://assets/mirrorhl_prox_forearm_03e__2.stl"/>
      </geometry>
      <material name="mirrorhl_prox_forearm_03e_2_material">
        <color rgba="0.972549 0.529412 0.00392157 1.0"/>
      </material>
    </visual>
    <collision>
      <origin xyz="5.55112e-17 4.85723e-17 -0.0342" rpy="-2.54286e-16 -8.45886e-17 4.61504e-18"/>
      <geometry>
        <mesh filename="package://assets/mirrorhl_prox_forearm_03e__2.stl"/>
      </geometry>
    </collision>
    <!-- Part mirrorhl_prox_forearm_03e_3 -->
    <visual>
      <origin xyz="2.77556e-17 -5.20417e-17 -0.0343" rpy="-2.68087e-16 -2.03732e-16 4.61504e-18"/>
      <geometry>
        <mesh filename="package://assets/mirrorhl_prox_forearm_03e__3.stl"/>
      </geometry>
      <material name="mirrorhl_prox_forearm_03e_3_material">
        <color rgba="0.231373 0.380392 0.705882 1.0"/>
      </material>
    </visual>
    <collision>
      <origin xyz="2.77556e-17 -5.20417e-17 -0.0343" rpy="-2.68087e-16 -2.03732e-16 4.61504e-18"/>
      <geometry>
        <mesh filename="package://assets/mirrorhl_prox_forearm_03e__3.stl"/>
      </geometry>
    </collision>
    <!-- Part mirrorhl_prox_forearm_03e_4 -->
    <visual>
      <origin xyz="0 0 -0.0344" rpy="-4.10524e-18 -1.98852e-31 1.16274e-30"/>
      <geometry>
        <mesh filename="package://assets/mirrorhl_prox_forearm_03e__4.stl"/>
      </geometry>
      <material name="mirrorhl_prox_forearm_03e_4_material">
        <color rgba="0.768627 0.886275 0.952941 1.0"/>
      </material>
    </visual>
    <collision>
      <origin xyz="0 0 -0.0344" rpy="-4.10524e-18 -1.98852e-31 1.16274e-30"/>
      <geometry>
        <mesh filename="package://assets/mirrorhl_prox_forearm_03e__4.stl"/>
      </geometry>
    </collision>
  </link>
  <!-- Link hl_fore_arm_02c_part_01j -->
  <link name="hl_fore_arm_02c_part_01j">
    <inertial>
      <origin xyz="-0.00140027 0.00320085 -0.0425478" rpy="0 0 0"/>
      <mass value="0.0971945"/>
      <inertia ixx="8.35224e-05" ixy="1.88422e-07" ixz="-1.65249e-06" iyy="7.7724e-05" iyz="2.92982e-06" izz="6.65178e-05"/>
    </inertial>
    <!-- Part hl_fore_arm_02c_part_01j -->
    <visual>
      <origin xyz="-0.049131 0.110858 0.285457" rpy="-2.76267 -1.37372 1.24097e-17"/>
      <geometry>
        <mesh filename="package://assets/hl_fore_arm_02c_part_01j.stl"/>
      </geometry>
      <material name="hl_fore_arm_02c_part_01j_material">
        <color rgba="0.231373 0.380392 0.705882 1.0"/>
      </material>
    </visual>
    <collision>
      <origin xyz="-0.049131 0.110858 0.285457" rpy="-2.76267 -1.37372 1.24097e-17"/>
      <geometry>
        <mesh filename="package://assets/hl_fore_arm_02c_part_01j.stl"/>
      </geometry>
    </collision>
    <!-- Part hl_fore_arm_02c_part_01j_2 -->
    <visual>
      <origin xyz="-0.0491308 0.110857 0.285457" rpy="-2.76267 -1.37372 -1.59391e-15"/>
      <geometry>
        <mesh filename="package://assets/hl_fore_arm_02c_part_01j__2.stl"/>
      </geometry>
      <material name="hl_fore_arm_02c_part_01j_2_material">
        <color rgba="0.647059 0.647059 0.647059 1.0"/>
      </material>
    </visual>
    <collision>
      <origin xyz="-0.0491308 0.110857 0.285457" rpy="-2.76267 -1.37372 -1.59391e-15"/>
      <geometry>
        <mesh filename="package://assets/hl_fore_arm_02c_part_01j__2.stl"/>
      </geometry>
    </collision>
  </link>
  <!-- Joint from mirrorhl_prox_forearm_03e to hl_fore_arm_02c_part_01j -->
  <joint name="left_forearm_yaw" type="revolute">
    <origin xyz="-0.06438 -4.85723e-17 -0.0343" rpy="-1.5708 -6.95942e-16 -1.5708"/>
    <parent link="mirrorhl_prox_forearm_03e"/>
    <child link="hl_fore_arm_02c_part_01j"/>
    <axis xyz="0 0 1"/>
    <limit effort="10" velocity="10" lower="-3.141592653589793" upper="3.141592653589793"/>
  </joint>
  <!-- Joint from mirrorhl_hum_elbow_03 to mirrorhl_prox_forearm_03e -->
  <joint name="left_elbow_pitch" type="revolute">
    <origin xyz="0.0382 0.0324 -0.056" rpy="-1.5708 -1.5708 0"/>
    <parent link="mirrorhl_hum_elbow_03"/>
    <child link="mirrorhl_prox_forearm_03e"/>
    <axis xyz="0 0 1"/>
    <limit effort="10" velocity="10" lower="-3.141592653589793" upper="3.141592653589793"/>
  </joint>
  <!-- Joint from mirrorhl_humeral_03a to mirrorhl_hum_elbow_03 -->
  <joint name="left_elbow_yaw" type="revolute">
    <origin xyz="-0.1438 -5e-05 0.0409065" rpy="-1.5708 1.56326 -1.5708"/>
    <parent link="mirrorhl_humeral_03a"/>
    <child link="mirrorhl_hum_elbow_03"/>
    <axis xyz="0 0 1"/>
    <limit effort="10" velocity="10" lower="-3.141592653589793" upper="3.141592653589793"/>
  </joint>
  <!-- Joint from mirrorhl_shoulder_yaw_03a to mirrorhl_humeral_03a -->
  <joint name="left_shoulder_roll" type="revolute">
    <origin xyz="-0.0403 1.35174e-05 -0.0314" rpy="-1.5708 -5.03695e-16 -1.5708"/>
    <parent link="mirrorhl_shoulder_yaw_03a"/>
    <child link="mirrorhl_humeral_03a"/>
    <axis xyz="0 0 1"/>
    <limit effort="10" velocity="10" lower="-3.141592653589793" upper="3.141592653589793"/>
  </joint>
  <!-- Joint from thorax_02d to mirrorhl_shoulder_yaw_03a -->
  <joint name="left_shoulder_pitch" type="revolute">
    <origin xyz="0.00701727 0.175035 -0.0258308" rpy="-1.5708 -1.73472e-15 3.04441"/>
    <parent link="thorax_02d"/>
    <child link="mirrorhl_shoulder_yaw_03a"/>
    <axis xyz="0 0 1"/>
    <limit effort="10" velocity="10" lower="-3.141592653589793" upper="3.141592653589793"/>
  </joint>
</robot>
